Workbook

Sheet inputs
A2: Disch P=a*flow^2 + b*flow + c | J2: Disch P | K2: A Machine | L2: B Machine | M2: C Machine | N2: Total CPF Output
A3: Machine | B3: a | C3: b | D3: c | J3: 2200 | K3: =-($C$4+SQRT($C$4^2-4*$B$4*$D$4+4*$B$4*J3))/(2*$B$4) -> 41361.299 | L3: =-($C$5+SQRT($C$5^2-4*$B$5*$D$5+4*$B$5*J3))/(2*$B$5) -> 40781.578 | M3: =-($C$6+SQRT($C$6^2-4*$B$6*$D$6+4*$B$6*J3))/(2*$B$6) -> 43757.64 | N3: =+K3+L3+M3 -> 125900.52
A4: A | B4: -6.609506e-07 | C4: -0.015489712 | D4: 3971.4005 | J4: 2300 | K4: =-($C$4+SQRT($C$4^2-4*$B$4*$D$4+4*$B$4*J4))/(2*$B$4) -> 39916.427 | L4: =-($C$5+SQRT($C$5^2-4*$B$5*$D$5+4*$B$5*J4))/(2*$B$5) -> 39242.833 | M4: =-($C$6+SQRT($C$6^2-4*$B$6*$D$6+4*$B$6*J4))/(2*$B$6) -> 42392.176 | N4: =+K4+L4+M4 -> 121551.44
A5: B | B5: -1.0008492e-06 | C5: 0.015104374 | D5: 3248.5693 | J5: 2400 | K5: =-($C$4+SQRT($C$4^2-4*$B$4*$D$4+4*$B$4*J5))/(2*$B$4) -> 38429.942 | L5: =-($C$5+SQRT($C$5^2-4*$B$5*$D$5+4*$B$5*J5))/(2*$B$5) -> 37625.474 | M5: =-($C$6+SQRT($C$6^2-4*$B$6*$D$6+4*$B$6*J5))/(2*$B$6) -> 40927.427 | N5: =+K5+L5+M5 -> 116982.84
A6: C | B6: -1.75395e-06 | C6: 0.077867326 | D6: 2151.0521 | J6: 2500 | K6: =-($C$4+SQRT($C$4^2-4*$B$4*$D$4+4*$B$4*J6))/(2*$B$4) -> 36898.027 | L6: =-($C$5+SQRT($C$5^2-4*$B$5*$D$5+4*$B$5*J6))/(2*$B$5) -> 35916.061 | M6: =-($C$6+SQRT($C$6^2-4*$B$6*$D$6+4*$B$6*J6))/(2*$B$6) -> 39337.959 | N6: =+K6+L6+M6 -> 112152.05
J7: 2600 | K7: =-($C$4+SQRT($C$4^2-4*$B$4*$D$4+4*$B$4*J7))/(2*$B$4) -> 35316.244 | L7: =-($C$5+SQRT($C$5^2-4*$B$5*$D$5+4*$B$5*J7))/(2*$B$5) -> 34096.82 | M7: =-($C$6+SQRT($C$6^2-4*$B$6*$D$6+4*$B$6*J7))/(2*$B$6) -> 37585.172 | N7: =+K7+L7+M7 -> 106998.24
A8: Pressure Drop from CFP to Pad | J8: 2700 | K8: =-($C$4+SQRT($C$4^2-4*$B$4*$D$4+4*$B$4*J8))/(2*$B$4) -> 33679.379 | L8: =-($C$5+SQRT($C$5^2-4*$B$5*$D$5+4*$B$5*J8))/(2*$B$5) -> 32143.393 | M8: =-($C$6+SQRT($C$6^2-4*$B$6*$D$6+4*$B$6*J8))/(2*$B$6) -> 35605.165 | N8: =+K8+L8+M8 -> 101427.94
J9: 2800 | K9: =-($C$4+SQRT($C$4^2-4*$B$4*$D$4+4*$B$4*J9))/(2*$B$4) -> 31981.244 | L9: =-($C$5+SQRT($C$5^2-4*$B$5*$D$5+4*$B$5*J9))/(2*$B$5) -> 30020.82 | M9: =-($C$6+SQRT($C$6^2-4*$B$6*$D$6+4*$B$6*J9))/(2*$B$6) -> 33276.776 | N9: =+K9+L9+M9 -> 95278.84
A10: B | B10: =2697-2425 -> 272 | J10: 2900 | K10: =-($C$4+SQRT($C$4^2-4*$B$4*$D$4+4*$B$4*J10))/(2*$B$4) -> 30214.396 | L10: =-($C$5+SQRT($C$5^2-4*$B$5*$D$5+4*$B$5*J10))/(2*$B$5) -> 27675.666 | M10: =-($C$6+SQRT($C$6^2-4*$B$6*$D$6+4*$B$6*J10))/(2*$B$6) -> 30305.21 | N10: =+K10+L10+M10 -> 88195.272
A11: G | B11: =2697-2404 -> 293 | J11: 3000 | K11: =-($C$4+SQRT($C$4^2-4*$B$4*$D$4+4*$B$4*J11))/(2*$B$4) -> 28369.75 | L11: =-($C$5+SQRT($C$5^2-4*$B$5*$D$5+4*$B$5*J11))/(2*$B$5) -> 25018.535 | M11: =-($C$6+SQRT($C$6^2-4*$B$6*$D$6+4*$B$6*J11))/(2*$B$6) -> 25150.242 | N11: =+K11+L11+M11 -> 78538.526
A12: H | B12: =2697-2442 -> 255
A13: J | B13: =2697-2446 -> 251

Sheet inputs_dec25
O1: BHP based on PF Pressure | U1: Liquid Rate | AA1: Oil Rate
A2: PW Pumps Coefficients | E2: Disch P=a*flow^2 + b*flow + c
A3: Machine | B3: a | C3: b | D3: c | AI3: =+Summary!AC53-Summary!AC54 -> 3.3565083
A4: A | B4: -6.609506e-07 | C4: -0.015489712 | D4: 3971.4005 | AI4: =+Summary!AC54-Summary!AC55 -> 3.3565083
A5: B | B5: -1.0008492e-06 | C5: 0.015104374 | D5: 3248.5693 | AI5: =+Summary!AC55-Summary!AC56 -> 3.3565083
A6: C | B6: -1.75395e-06 | C6: 0.077867326 | D6: 2151.0521 | AI6: =+Summary!AC56-Summary!AC57 -> 3.3565083
AI7: =+Summary!AC57-Summary!AC58 -> 3.3565083
AI8: =+Summary!AC58-Summary!AC59 -> 3.3565083
A9: Well PF Pres vs BHP Coefficients | D9: BHP = m*PF_pres + b | AI9: =+Summary!AC59-Summary!AC60 -> 3.3565083
A10: well | B10: m | C10: b | AI10: =+Summary!AC60-Summary!AC61 -> 3.3565083
A11: MPB-28 | B11: 0.58218234 | C11: -203.64747 | AI11: =+Summary!AC61-AH12 -> 2181.9793
A12: MPB-30 | B12: 0.25549302 | C12: 601.39385
A13: MPB-32 | B13: -0.12452145 | C13: 804.71813
A14: MPB-35 | B14: -0.32280481 | C14: 1239.9326 | J14: Well | K14: 2200 | L14: 2300 | M14: 2400 | N14: 2500 | Q14: 2600 | R14: 2700 | S14: 2800 | T14: 2900
A15: MPB-37 | B15: -0.036146351 | C15: 603.92011 | J15: MPB-28 | K15: =+$B$11*K14+$C$11 -> 1077.1537 | L15: =+$B$11*L14+$C$11 -> 1135.3719 | M15: =+$B$11*M14+$C$11 -> 1193.5901 | N15: =+$B$11*N14+$C$11 -> 1251.8084 | Q15: =+$B$11*Q14+$C$11 -> 1310.0266 | R15: =+$B$11*R14+$C$11 -> 1368.2448 | S15: =+$B$11*S14+$C$11 -> 1426.4631 | T15: =+$B$11*T14+$C$11 -> 1484.6813
A16: MPB-39 | B16: 0.032483409 | C16: 237.99647 | J16: MPB-30 | K16: =+$B$12*K14+$C$12 -> 1163.4785 | L16: =+$B$12*L14+$C$12 -> 1189.0278 | M16: =+$B$12*M14+$C$12 -> 1214.5771 | N16: =+$B$12*N14+$C$12 -> 1240.1264 | Q16: =+$B$12*Q14+$C$12 -> 1265.6757 | R16: =+$B$12*R14+$C$12 -> 1291.225 | S16: =+$B$12*S14+$C$12 -> 1316.7743 | T16: =+$B$12*T14+$C$12 -> 1342.3236
A17: MPG-16 | B17: 0.033759687 | C17: 543.62926 | J17: MPB-32 | K17: =+$B$13*K14+$C$13 -> 530.77093 | L17: =+$B$13*L14+$C$13 -> 518.31879 | M17: =+$B$13*M14+$C$13 -> 505.86664 | N17: =+$B$13*N14+$C$13 -> 493.4145 | Q17: =+$B$13*Q14+$C$13 -> 480.96235 | R17: =+$B$13*R14+$C$13 -> 468.51021 | S17: =+$B$13*S14+$C$13 -> 456.05806 | T17: =+$B$13*T14+$C$13 -> 443.60592
A18: MPG-18 | B18: -0.02996678 | C18: 856.79768 | J18: MPB-35 | K18: =+$B$14*K14+$C$14 -> 529.76207 | L18: =+$B$14*L14+$C$14 -> 497.48159 | M18: =+$B$14*M14+$C$14 -> 465.20111 | N18: =+$B$14*N14+$C$14 -> 432.92063 | Q18: =+$B$14*Q14+$C$14 -> 400.64015 | R18: =+$B$14*R14+$C$14 -> 368.35967 | S18: =+$B$14*S14+$C$14 -> 336.07919 | T18: =+$B$14*T14+$C$14 -> 303.79871
A19: MPH-16 | B19: -0.0052657081 | C19: 629.33288 | J19: MPB-37 | K19: =+$B$15*K14+$C$15 -> 524.39814 | L19: =+$B$15*L14+$C$15 -> 520.78351 | M19: =+$B$15*M14+$C$15 -> 517.16887 | N19: =+$B$15*N14+$C$15 -> 513.55423 | Q19: =+$B$15*Q14+$C$15 -> 509.9396 | R19: =+$B$15*R14+$C$15 -> 506.32496 | S19: =+$B$15*S14+$C$15 -> 502.71033 | T19: =+$B$15*T14+$C$15 -> 499.09569
A20: MPH-19 | B20: -0.020427951 | C20: 865.76376 | J20: MPB-39 | K20: =+$B$16*K14+$C$16 -> 309.45997 | L20: =+$B$16*L14+$C$16 -> 312.70832 | M20: =+$B$16*M14+$C$16 -> 315.95666 | N20: =+$B$16*N14+$C$16 -> 319.205 | Q20: =+$B$16*Q14+$C$16 -> 322.45334 | R20: =+$B$16*R14+$C$16 -> 325.70168 | S20: =+$B$16*S14+$C$16 -> 328.95002 | T20: =+$B$16*T14+$C$16 -> 332.19836
A21: MPJ-27 | B21: -0.056816462 | C21: 726.60211 | J21: MPG-16 | K21: =+$B$17*K14+$C$17 -> 617.90057 | L21: =+$B$17*L14+$C$17 -> 621.27654 | M21: =+$B$17*M14+$C$17 -> 624.65251 | N21: =+$B$17*N14+$C$17 -> 628.02848 | Q21: =+$B$17*Q14+$C$17 -> 631.40445 | R21: =+$B$17*R14+$C$17 -> 634.78042 | S21: =+$B$17*S14+$C$17 -> 638.15638 | T21: =+$B$17*T14+$C$17 -> 641.53235
J22: MPG-18 | K22: =+$B$18*K14+$C$18 -> 790.87076 | L22: =+$B$18*L14+$C$18 -> 787.87409 | M22: =+$B$18*M14+$C$18 -> 784.87741 | N22: =+$B$18*N14+$C$18 -> 781.88073 | Q22: =+$B$18*Q14+$C$18 -> 778.88405 | R22: =+$B$18*R14+$C$18 -> 775.88737 | S22: =+$B$18*S14+$C$18 -> 772.8907 | T22: =+$B$18*T14+$C$18 -> 769.89402
J23: MPH-16 | K23: =+$B$19*K14+$C$19 -> 617.74833 | L23: =+$B$19*L14+$C$19 -> 617.22176 | M23: =+$B$19*M14+$C$19 -> 616.69518 | N23: =+$B$19*N14+$C$19 -> 616.16861 | Q23: =+$B$19*Q14+$C$19 -> 615.64204 | R23: =+$B$19*R14+$C$19 -> 615.11547 | S23: =+$B$19*S14+$C$19 -> 614.5889 | T23: =+$B$19*T14+$C$19 -> 614.06233
A24: Well BHP vs Liquid Rate Coefficients | D24: Total Fluid = m*BHP + b | J24: MPH-19 | K24: =+$B$20*K14+$C$20 -> 820.82226 | L24: =+$B$20*L14+$C$20 -> 818.77947 | M24: =+$B$20*M14+$C$20 -> 816.73667 | N24: =+$B$20*N14+$C$20 -> 814.69388 | Q24: =+$B$20*Q14+$C$20 -> 812.65108 | R24: =+$B$20*R14+$C$20 -> 810.60829 | S24: =+$B$20*S14+$C$20 -> 808.56549 | T24: =+$B$20*T14+$C$20 -> 806.5227
A25: well | B25: m | C25: b | J25: MPJ-27 | K25: =+$B$21*K14+$C$21 -> 601.60589 | L25: =+$B$21*L14+$C$21 -> 595.92424 | M25: =+$B$21*M14+$C$21 -> 590.2426 | N25: =+$B$21*N14+$C$21 -> 584.56095 | Q25: =+$B$21*Q14+$C$21 -> 578.87931 | R25: =+$B$21*R14+$C$21 -> 573.19766 | S25: =+$B$21*S14+$C$21 -> 567.51601 | T25: =+$B$21*T14+$C$21 -> 561.83437
A26: MPB-28 | B26: -1.9065092 | C26: 3847.455
A27: MPB-30 | B27: 2.6776221 | C27: -2179.987
A28: MPB-32 | B28: 0.30836586 | C28: 642.33601
A29: MPB-35 | B29: 0.18901211 | C29: 64.451552 | E29: =+C29/B29 -> 340.99166
A30: MPB-37 | B30: -1.0696708 | C30: 1404.3918
A31: MPB-39 | B31: 6.371066 | C31: -1584.139
A32: MPG-16 | B32: -1.8242039 | C32: 1310.633
A33: MPG-18 | B33: -0.98447395 | C33: 1933.2378
A34: MPH-16 | B34: 0.38564646 | C34: 238.06015
A35: MPH-19 | B35: -25.485786 | C35: 21057.233
A36: MPJ-27 | B36: 3.8773981e-17 | C36: -23.30213
B37: -3.0277504e-16 | C37: 409.1355
A38: well | B38: PI | C38: WC
A39: MPB-28 | B39: -2.4377444 | C39: 0.73
A40: MPB-30 | B40: 0.71135684 | C40: 0.837
...

Sheet inputs_dec15
A2: PW Pumps Coefficients | E2: Disch P=a*flow^2 + b*flow + c
A3: Machine | B3: a | C3: b | D3: c | AH3: =+Summary!AC39-Summary!AC40 -> 46.410625
A4: A | B4: -6.609506e-07 | C4: -0.015489712 | D4: 3971.4005 | AH4: =+Summary!AC40-Summary!AC41 -> 46.410625
A5: B | B5: -1.0008492e-06 | C5: 0.015104374 | D5: 3248.5693 | AH5: =+Summary!AC41-Summary!AC42 -> 46.410625
A6: C | B6: -1.75395e-06 | C6: 0.077867326 | D6: 2151.0521 | AH6: =+Summary!AC42-Summary!AC43 -> 46.410625
AH7: =+Summary!AC43-Summary!AC44 -> 46.410625
AH8: =+Summary!AC44-Summary!AC45 -> 46.410625
A9: Well PF Pres vs BHP Coefficients | D9: BHP = m*PF_pres + b | AH9: =+Summary!AC45-Summary!AC46 -> 46.410625
A10: well | B10: m | C10: b | AH10: =+Summary!AC46-Summary!AC47 -> 46.410625
A11: MPB-28 | B11: 0.58218234 | C11: -203.64747 | AH11: =+Summary!AC47-AG12 -> 1685.6492
A12: MPB-30 | B12: 0.25549302 | C12: 601.39385
A13: MPB-32 | B13: -0.12452145 | C13: 804.71813
A14: MPB-35 | B14: -0.32280481 | C14: 1239.9326 | J14: Well | K14: 2200 | L14: 2300 | M14: 2400 | N14: 2500 | Q14: 2600 | R14: 2700 | S14: 2800 | T14: 2900
A15: MPB-37 | B15: -0.036146351 | C15: 603.92011 | J15: MPB-28 | K15: =+$B$11*K14+$C$11 -> 1077.1537 | L15: =+$B$11*L14+$C$11 -> 1135.3719 | M15: =+$B$11*M14+$C$11 -> 1193.5901 | N15: =+$B$11*N14+$C$11 -> 1251.8084 | Q15: =+$B$11*Q14+$C$11 -> 1310.0266 | R15: =+$B$11*R14+$C$11 -> 1368.2448 | S15: =+$B$11*S14+$C$11 -> 1426.4631 | T15: =+$B$11*T14+$C$11 -> 1484.6813
A16: MPB-39 | B16: 0.032483409 | C16: 237.99647 | J16: MPB-30 | K16: =+$B$12*K14+$C$12 -> 1163.4785 | L16: =+$B$12*L14+$C$12 -> 1189.0278 | M16: =+$B$12*M14+$C$12 -> 1214.5771 | N16: =+$B$12*N14+$C$12 -> 1240.1264 | Q16: =+$B$12*Q14+$C$12 -> 1265.6757 | R16: =+$B$12*R14+$C$12 -> 1291.225 | S16: =+$B$12*S14+$C$12 -> 1316.7743 | T16: =+$B$12*T14+$C$12 -> 1342.3236
A17: MPG-16 | B17: 0.033759687 | C17: 543.62926 | J17: MPB-32 | K17: =+$B$13*K14+$C$13 -> 530.77093 | L17: =+$B$13*L14+$C$13 -> 518.31879 | M17: =+$B$13*M14+$C$13 -> 505.86664 | N17: =+$B$13*N14+$C$13 -> 493.4145 | Q17: =+$B$13*Q14+$C$13 -> 480.96235 | R17: =+$B$13*R14+$C$13 -> 468.51021 | S17: =+$B$13*S14+$C$13 -> 456.05806 | T17: =+$B$13*T14+$C$13 -> 443.60592
A18: MPG-18 | B18: -0.02996678 | C18: 856.79768 | J18: MPB-35 | K18: =+$B$14*K14+$C$14 -> 529.76207 | L18: =+$B$14*L14+$C$14 -> 497.48159 | M18: =+$B$14*M14+$C$14 -> 465.20111 | N18: =+$B$14*N14+$C$14 -> 432.92063 | Q18: =+$B$14*Q14+$C$14 -> 400.64015 | R18: =+$B$14*R14+$C$14 -> 368.35967 | S18: =+$B$14*S14+$C$14 -> 336.07919 | T18: =+$B$14*T14+$C$14 -> 303.79871
A19: MPH-16 | B19: -0.0052657081 | C19: 629.33288 | J19: MPB-37 | K19: =+$B$15*K14+$C$15 -> 524.39814 | L19: =+$B$15*L14+$C$15 -> 520.78351 | M19: =+$B$15*M14+$C$15 -> 517.16887 | N19: =+$B$15*N14+$C$15 -> 513.55423 | Q19: =+$B$15*Q14+$C$15 -> 509.9396 | R19: =+$B$15*R14+$C$15 -> 506.32496 | S19: =+$B$15*S14+$C$15 -> 502.71033 | T19: =+$B$15*T14+$C$15 -> 499.09569
A20: MPH-19 | B20: -0.020427951 | C20: 865.76376 | J20: MPB-39 | K20: =+$B$16*K14+$C$16 -> 309.45997 | L20: =+$B$16*L14+$C$16 -> 312.70832 | M20: =+$B$16*M14+$C$16 -> 315.95666 | N20: =+$B$16*N14+$C$16 -> 319.205 | Q20: =+$B$16*Q14+$C$16 -> 322.45334 | R20: =+$B$16*R14+$C$16 -> 325.70168 | S20: =+$B$16*S14+$C$16 -> 328.95002 | T20: =+$B$16*T14+$C$16 -> 332.19836
A21: MPJ-27 | B21: -0.056816462 | C21: 726.60211 | J21: MPG-16 | K21: =+$B$17*K14+$C$17 -> 617.90057 | L21: =+$B$17*L14+$C$17 -> 621.27654 | M21: =+$B$17*M14+$C$17 -> 624.65251 | N21: =+$B$17*N14+$C$17 -> 628.02848 | Q21: =+$B$17*Q14+$C$17 -> 631.40445 | R21: =+$B$17*R14+$C$17 -> 634.78042 | S21: =+$B$17*S14+$C$17 -> 638.15638 | T21: =+$B$17*T14+$C$17 -> 641.53235
J22: MPG-18 | K22: =+$B$18*K14+$C$18 -> 790.87076 | L22: =+$B$18*L14+$C$18 -> 787.87409 | M22: =+$B$18*M14+$C$18 -> 784.87741 | N22: =+$B$18*N14+$C$18 -> 781.88073 | Q22: =+$B$18*Q14+$C$18 -> 778.88405 | R22: =+$B$18*R14+$C$18 -> 775.88737 | S22: =+$B$18*S14+$C$18 -> 772.8907 | T22: =+$B$18*T14+$C$18 -> 769.89402
J23: MPH-16 | K23: =+$B$19*K14+$C$19 -> 617.74833 | L23: =+$B$19*L14+$C$19 -> 617.22176 | M23: =+$B$19*M14+$C$19 -> 616.69518 | N23: =+$B$19*N14+$C$19 -> 616.16861 | Q23: =+$B$19*Q14+$C$19 -> 615.64204 | R23: =+$B$19*R14+$C$19 -> 615.11547 | S23: =+$B$19*S14+$C$19 -> 614.5889 | T23: =+$B$19*T14+$C$19 -> 614.06233
A24: Well BHP vs Liquid Rate Coefficients | D24: Total Fluid = m*BHP + b | J24: MPH-19 | K24: =+$B$20*K14+$C$20 -> 820.82226 | L24: =+$B$20*L14+$C$20 -> 818.77947 | M24: =+$B$20*M14+$C$20 -> 816.73667 | N24: =+$B$20*N14+$C$20 -> 814.69388 | Q24: =+$B$20*Q14+$C$20 -> 812.65108 | R24: =+$B$20*R14+$C$20 -> 810.60829 | S24: =+$B$20*S14+$C$20 -> 808.56549 | T24: =+$B$20*T14+$C$20 -> 806.5227
A25: well | B25: m | C25: b | J25: MPJ-27 | K25: =+$B$21*K14+$C$21 -> 601.60589 | L25: =+$B$21*L14+$C$21 -> 595.92424 | M25: =+$B$21*M14+$C$21 -> 590.2426 | N25: =+$B$21*N14+$C$21 -> 584.56095 | Q25: =+$B$21*Q14+$C$21 -> 578.87931 | R25: =+$B$21*R14+$C$21 -> 573.19766 | S25: =+$B$21*S14+$C$21 -> 567.51601 | T25: =+$B$21*T14+$C$21 -> 561.83437
A26: MPB-28 | B26: -2.4377444 | C26: 4140.8882
A27: MPB-30 | B27: 0.71135684 | C27: -25.762458
A28: MPB-32 | B28: 1.5300796 | C28: -146.38822
A29: MPB-35 | B29: 0.14049218 | C29: 64.090187 | E29: =+C29/B29 -> 456.18331
A30: MPB-37 | B30: 0.17258408 | C30: 729.24319
A31: MPB-39 | B31: 0.408712 | C31: 178.98826
A32: MPG-02 | B32: -1.9093674 | C32: 1354.8119
A33: MPG-14 | B33: -0.98447395 | C33: 1933.2378
A34: MPG-16 | B34: -9.8255837 | C34: 6540.0025
A35: MPG-18 | B35: -4.6984387 | C35: 4637.3572
A36: MPH-16 | B36: 3.8773981e-17 | C36: -23.30213
A37: MPH-19 | B37: -2.5879953e-16 | C37: 409.1355
A39: well | B39: PI | C39: WC
A40: MPB-28 | B40: -2.4377444 | C40: 0.73
A41: MPB-30 | B41: 0.71135684 | C41: 0.837
A42: MPB-32 | B42: 1.5300796 | C42: 0.54
...

Sheet inputs_dec1
A2: PW Pumps Coefficients | E2: Disch P=a*flow^2 + b*flow + c
A3: Machine | B3: a | C3: b | D3: c | AI3: =+Summary!AC26-Summary!AC27 -> 3.9906412
A4: A | B4: -6.609506e-07 | C4: -0.015489712 | D4: 3971.4005 | AI4: =+Summary!AC27-Summary!AC28 -> 3.9906412
A5: B | B5: -1.0008492e-06 | C5: 0.015104374 | D5: 3248.5693 | AI5: =+Summary!AC28-Summary!AC29 -> 3.9906412
A6: C | B6: -1.75395e-06 | C6: 0.077867326 | D6: 2151.0521 | AI6: =+Summary!AC29-Summary!AC30 -> 3.9906412
AI7: =+Summary!AC30-Summary!AC31 -> 3.9906412
AI8: =+Summary!AC31-Summary!AC32 -> 3.9906412
A9: Well PF Pres vs BHP Coefficients | D9: BHP = m*PF_pres + b | AI9: =+Summary!AC32-Summary!AC33 -> 3.9906412
A10: well | B10: m | C10: b | AI10: =+Summary!AC33-Summary!AC34 -> 3.9906412
A11: MPB-28 | B11: -0.11579174 | C11: 1442.0212 | AI11: =+Summary!AC34-AH12 -> 1843.4886
A12: MPB-30 | B12: 0.25549302 | C12: 601.39385
A13: MPB-32 | B13: -0.1389804 | C13: 779.07049
A14: MPB-35 | B14: -0.089168669 | C14: 678.62931 | J14: Well | K14: 2200 | L14: 2300 | M14: 2400 | N14: 2500 | Q14: 2600 | R14: 2700 | S14: 2800 | T14: 2900
A15: MPB-37 | B15: -0.0080299117 | C15: 534.46196 | J15: MPB-28 | K15: =+$B$11*K14+$C$11 -> 1187.2793 | L15: =+$B$11*L14+$C$11 -> 1175.7002 | M15: =+$B$11*M14+$C$11 -> 1164.121 | N15: =+$B$11*N14+$C$11 -> 1152.5418 | Q15: =+$B$11*Q14+$C$11 -> 1140.9627 | R15: =+$B$11*R14+$C$11 -> 1129.3835 | S15: =+$B$11*S14+$C$11 -> 1117.8043 | T15: =+$B$11*T14+$C$11 -> 1106.2251
A16: MPB-39 | B16: 0.031361925 | C16: 251.26995 | J16: MPB-30 | K16: =+$B$12*K14+$C$12 -> 1163.4785 | L16: =+$B$12*L14+$C$12 -> 1189.0278 | M16: =+$B$12*M14+$C$12 -> 1214.5771 | N16: =+$B$12*N14+$C$12 -> 1240.1264 | Q16: =+$B$12*Q14+$C$12 -> 1265.6757 | R16: =+$B$12*R14+$C$12 -> 1291.225 | S16: =+$B$12*S14+$C$12 -> 1316.7743 | T16: =+$B$12*T14+$C$12 -> 1342.3236
A17: MPG-16 | B17: -0.0065327537 | C17: 646.25727 | J17: MPB-32 | K17: =+$B$13*K14+$C$13 -> 473.31361 | L17: =+$B$13*L14+$C$13 -> 459.41557 | M17: =+$B$13*M14+$C$13 -> 445.51753 | N17: =+$B$13*N14+$C$13 -> 431.61949 | Q17: =+$B$13*Q14+$C$13 -> 417.72145 | R17: =+$B$13*R14+$C$13 -> 403.82341 | S17: =+$B$13*S14+$C$13 -> 389.92537 | T17: =+$B$13*T14+$C$13 -> 376.02732
A18: MPG-18 | B18: -0.016849836 | C18: 817.77531 | J18: MPB-35 | K18: =+$B$14*K14+$C$14 -> 482.45824 | L18: =+$B$14*L14+$C$14 -> 473.54137 | M18: =+$B$14*M14+$C$14 -> 464.62451 | N18: =+$B$14*N14+$C$14 -> 455.70764 | Q18: =+$B$14*Q14+$C$14 -> 446.79077 | R18: =+$B$14*R14+$C$14 -> 437.87391 | S18: =+$B$14*S14+$C$14 -> 428.95704 | T18: =+$B$14*T14+$C$14 -> 420.04017
A19: MPH-16 | B19: -0.016142698 | C19: 679.17506 | J19: MPB-37 | K19: =+$B$15*K14+$C$15 -> 516.79615 | L19: =+$B$15*L14+$C$15 -> 515.99316 | M19: =+$B$15*M14+$C$15 -> 515.19017 | N19: =+$B$15*N14+$C$15 -> 514.38718 | Q19: =+$B$15*Q14+$C$15 -> 513.58419 | R19: =+$B$15*R14+$C$15 -> 512.7812 | S19: =+$B$15*S14+$C$15 -> 511.97821 | T19: =+$B$15*T14+$C$15 -> 511.17522
A20: MPH-19 | B20: -0.010764676 | C20: 836.46351 | J20: MPB-39 | K20: =+$B$16*K14+$C$16 -> 320.26619 | L20: =+$B$16*L14+$C$16 -> 323.40238 | M20: =+$B$16*M14+$C$16 -> 326.53858 | N20: =+$B$16*N14+$C$16 -> 329.67477 | Q20: =+$B$16*Q14+$C$16 -> 332.81096 | R20: =+$B$16*R14+$C$16 -> 335.94715 | S20: =+$B$16*S14+$C$16 -> 339.08335 | T20: =+$B$16*T14+$C$16 -> 342.21954
A21: MPJ-27 | B21: -0.010730247 | C21: 603.50903 | J21: MPG-16 | K21: =+$B$17*K14+$C$17 -> 631.88521 | L21: =+$B$17*L14+$C$17 -> 631.23193 | M21: =+$B$17*M14+$C$17 -> 630.57866 | N21: =+$B$17*N14+$C$17 -> 629.92538 | Q21: =+$B$17*Q14+$C$17 -> 629.27211 | R21: =+$B$17*R14+$C$17 -> 628.61883 | S21: =+$B$17*S14+$C$17 -> 627.96556 | T21: =+$B$17*T14+$C$17 -> 627.31228
J22: MPG-18 | K22: =+$B$18*K14+$C$18 -> 780.70567 | L22: =+$B$18*L14+$C$18 -> 779.02069 | M22: =+$B$18*M14+$C$18 -> 777.3357 | N22: =+$B$18*N14+$C$18 -> 775.65072 | Q22: =+$B$18*Q14+$C$18 -> 773.96574 | R22: =+$B$18*R14+$C$18 -> 772.28075 | S22: =+$B$18*S14+$C$18 -> 770.59577 | T22: =+$B$18*T14+$C$18 -> 768.91079
J23: MPH-16 | K23: =+$B$19*K14+$C$19 -> 643.66113 | L23: =+$B$19*L14+$C$19 -> 642.04686 | M23: =+$B$19*M14+$C$19 -> 640.43259 | N23: =+$B$19*N14+$C$19 -> 638.81832 | Q23: =+$B$19*Q14+$C$19 -> 637.20405 | R23: =+$B$19*R14+$C$19 -> 635.58978 | S23: =+$B$19*S14+$C$19 -> 633.97551 | T23: =+$B$19*T14+$C$19 -> 632.36124
A24: Well BHP vs Liquid Rate Coefficients | D24: Total Fluid = m*BHP + b | J24: MPH-19 | K24: =+$B$20*K14+$C$20 -> 812.78122 | L24: =+$B$20*L14+$C$20 -> 811.70475 | M24: =+$B$20*M14+$C$20 -> 810.62829 | N24: =+$B$20*N14+$C$20 -> 809.55182 | Q24: =+$B$20*Q14+$C$20 -> 808.47535 | R24: =+$B$20*R14+$C$20 -> 807.39888 | S24: =+$B$20*S14+$C$20 -> 806.32242 | T24: =+$B$20*T14+$C$20 -> 805.24595
A25: well | B25: m | C25: b | J25: MPJ-27 | K25: =+$B$21*K14+$C$21 -> 579.90249 | L25: =+$B$21*L14+$C$21 -> 578.82946 | M25: =+$B$21*M14+$C$21 -> 577.75644 | N25: =+$B$21*N14+$C$21 -> 576.68341 | Q25: =+$B$21*Q14+$C$21 -> 575.61039 | R25: =+$B$21*R14+$C$21 -> 574.53736 | S25: =+$B$21*S14+$C$21 -> 573.46434 | T25: =+$B$21*T14+$C$21 -> 572.39132
A26: MPB-28 | B26: -1.9065092 | C26: 3847.455
A27: MPB-30 | B27: 0.31030652 | C27: 418.35949
A28: MPB-32 | B28: 1.7380854 | C28: -234.94551
A29: MPB-35 | B29: 0.11653354 | C29: 115.79712 | E29: =+C29/B29 -> 993.6806
A30: MPB-37 | B30: 1.7798462 | C30: -196.42361
A31: MPB-39 | B31: 0.6787112 | C31: 112.15002
A32: MPG-02 | B32: -2.7156829 | C32: 1773.3875
A33: MPG-14 | B33: -0.98447395 | C33: 1933.2378
A34: MPG-16 | B34: -10.020263 | C34: 6621.4096
A35: MPG-18 | B35: 3.710729 | C35: -2012.2627
A36: MPH-16 | B36: -0.91294217 | C36: 874.02125
A37: MPH-19 | B37: -0.00054334694 | C37: 409.13247
A39: well | B39: PI | C39: WC
A40: MPB-28 | B40: -0.53631835 | C40: 0.73
A41: MPB-30 | B41: 4.7294774 | C41: 0.837
A42: MPB-32 | C42: 0.54
...

Sheet Summary
I7: Bottom Hole Change | R7: BHP Impact Combined Wells | S7: Oil Impact at 0% WC
H8: Disch P | I8: MPB-32 | J8: MPB-35 | K8: MPB-37 | L8: MPB-39 | M8: MPG-16 | N8: MPG-18 | O8: MPH-16 | P8: MPH-19 | Q8: MPJ-27 | R8: dBHP for 100 psi | S8: 1 bbl/psi
H9: 2200 | I9: 865.87339 | J9: 435.25212 | K9: 580.94342 | L9: 408.22366 | M9: 641.52115 | N9: 778.97013 | O9: 526.68856 | P9: 804.30063 | Q9: 558.6667 | R9: =(+I9-I10+J9-J10+K9-K10+L9-L10+M9-M10+N9-N10+O9-O10+P9-P10+Q9-+Q10) -> 20.517639 | S9: =+R9*1 -> 20.517639
H10: 2300 | I10: 850.81361 | J10: 435.72812 | K10: 580.30905 | L10: 406.7889 | M10: 641.22606 | N10: 778.83371 | O10: 525.10913 | P10: 804.2453 | Q10: 556.86825 | R10: =(+I10-I11+J10-J11+K10-K11+L10-L11+M10-M11+N10-N11+O10-O11+P10-P11+Q10-+Q11) -> 19.231569 | S10: =+R10*1 -> 19.231569
H11: 2400 | I11: 835.75384 | J11: 436.20411 | K11: 579.67468 | L11: 405.35413 | M11: 640.93098 | N11: 778.6973 | O11: 523.52969 | P11: 804.18996 | Q11: 556.35587 | R11: =(+I11-I12+J11-J12+K11-K12+L11-L12+M11-M12+N11-N12+O11-O12+P11-P12+Q11-+Q12) -> 19.231569 | S11: =+R11*1 -> 19.231569
H12: 2500 | I12: 820.69406 | J12: 436.68011 | K12: 579.04031 | L12: 403.91936 | M12: 640.6359 | N12: 778.56089 | O12: 521.95026 | P12: 804.13462 | Q12: 555.84349 | R12: =(+I12-I13+J12-J13+K12-K13+L12-L13+M12-M13+N12-N13+O12-O13+P12-P13+Q12-+Q13) -> 19.231569 | S12: =+R12*1 -> 19.231569
H13: 2600 | I13: 805.63428 | J13: 437.15611 | K13: 578.40593 | L13: 402.48459 | M13: 640.34082 | N13: 778.42447 | O13: 520.37082 | P13: 804.07928 | Q13: 555.33111 | R13: =(+I13-I14+J13-J14+K13-K14+L13-L14+M13-M14+N13-N14+O13-O14+P13-P14+Q13-+Q14) -> 19.231569 | S13: =+R13*1 -> 19.231569
H14: 2700 | I14: 790.5745 | J14: 437.6321 | K14: 577.77156 | L14: 401.04983 | M14: 640.04573 | N14: 778.28806 | O14: 518.79139 | P14: 804.02394 | Q14: 554.81873 | R14: =(+I14-I15+J14-J15+K14-K15+L14-L15+M14-M15+N14-N15+O14-O15+P14-P15+Q14-+Q15) -> 19.231569 | S14: =+R14*1 -> 19.231569
H15: 2800 | I15: 775.51473 | J15: 438.1081 | K15: 577.13719 | L15: 399.61506 | M15: 639.75065 | N15: 778.15165 | O15: 517.21195 | P15: 803.96861 | Q15: 554.30635 | R15: =(+I15-I16+J15-J16+K15-K16+L15-L16+M15-M16+N15-N16+O15-O16+P15-P16+Q15-+Q16) -> 19.231569 | S15: =+R15*1 -> 19.231569
H16: 2900 | I16: 760.45495 | J16: 438.5841 | K16: 576.50282 | L16: 398.18029 | M16: 639.45557 | N16: 778.01523 | O16: 515.63252 | P16: 803.91327 | Q16: 553.79397 | R16: =(+I16-I17+J16-J17+K16-K17+L16-L17+M16-M17+N16-N17+O16-O17+P16-P17+Q16-+Q17) -> 19.231569 | S16: =+R16*1 -> 19.231569
H17: 3000 | I17: 745.39517 | J17: 439.06009 | K17: 575.86845 | L17: 396.74552 | M17: 639.16048 | N17: 777.87882 | O17: 514.05308 | P17: 803.85793 | Q17: 553.28159 | S17: =+R17*1 -> 0
E24: 45627 | J24: BHP based on PF Pressure | P24: Liquid Rate | V24: Oil Rate
E25: Disch P | F25: A Machine | G25: B Machine | H25: C Machine | I25: Total CPF Output | J25: MPB-28 | K25: MPB-30 | L25: MPB-32 | M25: MPB-35 | N25: MPB-37 | O25: MPB-39 | P25: MPB-28 | Q25: MPB-30 | R25: MPB-32 | S25: MPB-35 | T25: MPB-37 | U25: MPB-39 | V25: MPB-28 | W25: MPB-30 | X25: MPB-32 | Y25: MPB-35 | Z25: MPB-37 | AA25: MPB-39 | AC25: Cum Oil
E26: 2200 | F26: =-(inputs_dec1!$C$4+SQRT(inputs_dec1!$C$4^2-4*inputs_dec1!$B$4*inputs_dec1!$D$4+4*inputs_dec1!$B$4*E26))/(2*inputs_dec1!$B$4) -> 41361.299 | G26: =-(inputs_dec1!$C$5+SQRT(inputs_dec1!$C$5^2-4*inputs_dec1!$B$5*inputs_dec1!$D$5+4*inputs_dec1!$B$5*E26))/(2*inputs_dec1!$B$5) -> 40781.578 | H26: =-(inputs_dec1!$C$6+SQRT(inputs_dec1!$C$6^2-4*inputs_dec1!$B$6*inputs_dec1!$D$6+4*inputs_dec1!$B$6*E26))/(2*inputs_dec1!$B$6) -> 43757.64 | I26: =+F26+G26+H26 -> 125900.52 | J26: =+inputs_dec1!$B$11*(E26-inputs_dec1!$B$54)+inputs_dec1!$C$11 -> 1218.7747 | K26: =+inputs_dec1!$B$12*(E26-inputs_dec1!$B$54)+inputs_dec1!$C$12 -> 1093.9844 | L26: =inputs_dec1!$B$13*(E26-inputs_dec1!$B$54)+inputs_dec1!$C$13 -> 511.11628 | M26: =+inputs_dec1!$B$14*(E26-inputs_dec1!$B$54)+inputs_dec1!$C$14 -> 506.71212 | N26: =+inputs_dec1!$B$15*(E26-inputs_dec1!$B$54)+inputs_dec1!$C$15 -> 518.98029 | O26: =+inputs_dec1!$B$16*(E26-inputs_dec1!$B$54)+inputs_dec1!$C$16 -> 311.73575 | P26: =inputs_dec1!$B$26*J26+inputs_dec1!$C$26 -> 1523.8498 | Q26: =inputs_dec1!$B$27*K26+inputs_dec1!$C$27 -> 757.82998 | R26: =inputs_dec1!$B$28*L26+inputs_dec1!$C$28 -> 653.41825 | S26: =inputs_dec1!$B$29*M26+inputs_dec1!$C$29 -> 174.84608 | T26: =inputs_dec1!$B$30*N26+inputs_dec1!$C$30 -> 727.28146 | U26: =inputs_dec1!$B$31*O26+inputs_dec1!$C$31 -> 323.72856 | V26: =+P26*(1-inputs_dec1!$C$40) -> 411.43946 | W26: =+Q26*(1-inputs_dec1!$C$41) -> 123.52629 | X26: =+R26*(1-inputs_dec1!$C$42) -> 300.5724 | Y26: =+S26*(1-inputs_dec1!$C$43) -> 110.15303 | Z26: =+T26*(1-inputs_dec1!$C$44) -> 654.55332 | AA26: =+U26*(1-inputs_dec1!$C$45) -> 275.16928 | AC26: =+SUM(V26:AA26) -> 1875.4138
E27: 2300 | F27: =-(inputs_dec1!$C$4+SQRT(inputs_dec1!$C$4^2-4*inputs_dec1!$B$4*inputs_dec1!$D$4+4*inputs_dec1!$B$4*E27))/(2*inputs_dec1!$B$4) -> 39916.427 | G27: =-(inputs_dec1!$C$5+SQRT(inputs_dec1!$C$5^2-4*inputs_dec1!$B$5*inputs_dec1!$D$5+4*inputs_dec1!$B$5*E27))/(2*inputs_dec1!$B$5) -> 39242.833 | H27: =-(inputs_dec1!$C$6+SQRT(inputs_dec1!$C$6^2-4*inputs_dec1!$B$6*inputs_dec1!$D$6+4*inputs_dec1!$B$6*E27))/(2*inputs_dec1!$B$6) -> 42392.176 | I27: =+F27+G27+H27 -> 121551.44 | J27: =+inputs_dec1!$B$11*(E27-inputs_dec1!$B$54)+inputs_dec1!$C$11 -> 1207.1955 | K27: =+inputs_dec1!$B$12*(E27-inputs_dec1!$B$54)+inputs_dec1!$C$12 -> 1119.5337 | L27: =inputs_dec1!$B$13*(E27-inputs_dec1!$B$54)+inputs_dec1!$C$13 -> 497.21824 | M27: =+inputs_dec1!$B$14*(E27-inputs_dec1!$B$54)+inputs_dec1!$C$14 -> 497.79525 | N27: =+inputs_dec1!$B$15*(E27-inputs_dec1!$B$54)+inputs_dec1!$C$15 -> 518.1773 | O27: =+inputs_dec1!$B$16*(E27-inputs_dec1!$B$54)+inputs_dec1!$C$16 -> 314.87194 | P27: =inputs_dec1!$B$26*J27+inputs_dec1!$C$26 -> 1545.9256 | Q27: =inputs_dec1!$B$27*K27+inputs_dec1!$C$27 -> 765.7581 | R27: =inputs_dec1!$B$28*L27+inputs_dec1!$C$28 -> 629.26227 | S27: =inputs_dec1!$B$29*M27+inputs_dec1!$C$29 -> 173.80696 | T27: =inputs_dec1!$B$30*N27+inputs_dec1!$C$30 -> 725.85226 | U27: =inputs_dec1!$B$31*O27+inputs_dec1!$C$31 -> 325.85713 | V27: =+P27*(1-inputs_dec1!$C$40) -> 417.39992 | W27: =+Q27*(1-inputs_dec1!$C$41) -> 124.81857 | X27: =+R27*(1-inputs_dec1!$C$42) -> 289.46065 | Y27: =+S27*(1-inputs_dec1!$C$43) -> 109.49839 | Z27: =+T27*(1-inputs_dec1!$C$44) -> 653.26703 | AA27: =+U27*(1-inputs_dec1!$C$45) -> 276.97856 | AC27: =+SUM(V27:AA27) -> 1871.4231
E28: 2400 | F28: =-(inputs_dec1!$C$4+SQRT(inputs_dec1!$C$4^2-4*inputs_dec1!$B$4*inputs_dec1!$D$4+4*inputs_dec1!$B$4*E28))/(2*inputs_dec1!$B$4) -> 38429.942 | G28: =-(inputs_dec1!$C$5+SQRT(inputs_dec1!$C$5^2-4*inputs_dec1!$B$5*inputs_dec1!$D$5+4*inputs_dec1!$B$5*E28))/(2*inputs_dec1!$B$5) -> 37625.474 | H28: =-(inputs_dec1!$C$6+SQRT(inputs_dec1!$C$6^2-4*inputs_dec1!$B$6*inputs_dec1!$D$6+4*inputs_dec1!$B$6*E28))/(2*inputs_dec1!$B$6) -> 40927.427 | I28: =+F28+G28+H28 -> 116982.84 | J28: =+inputs_dec1!$B$11*(E28-inputs_dec1!$B$54)+inputs_dec1!$C$11 -> 1195.6164 | K28: =+inputs_dec1!$B$12*(E28-inputs_dec1!$B$54)+inputs_dec1!$C$12 -> 1145.083 | L28: =inputs_dec1!$B$13*(E28-inputs_dec1!$B$54)+inputs_dec1!$C$13 -> 483.3202 | M28: =+inputs_dec1!$B$14*(E28-inputs_dec1!$B$54)+inputs_dec1!$C$14 -> 488.87838 | N28: =+inputs_dec1!$B$15*(E28-inputs_dec1!$B$54)+inputs_dec1!$C$15 -> 517.37431 | O28: =+inputs_dec1!$B$16*(E28-inputs_dec1!$B$54)+inputs_dec1!$C$16 -> 318.00813 | P28: =inputs_dec1!$B$26*J28+inputs_dec1!$C$26 -> 1568.0014 | Q28: =inputs_dec1!$B$27*K28+inputs_dec1!$C$27 -> 773.68621 | R28: =inputs_dec1!$B$28*L28+inputs_dec1!$C$28 -> 605.10629 | S28: =inputs_dec1!$B$29*M28+inputs_dec1!$C$29 -> 172.76785 | T28: =inputs_dec1!$B$30*N28+inputs_dec1!$C$30 -> 724.42306 | U28: =inputs_dec1!$B$31*O28+inputs_dec1!$C$31 -> 327.9857 | V28: =+P28*(1-inputs_dec1!$C$40) -> 423.36039 | W28: =+Q28*(1-inputs_dec1!$C$41) -> 126.11085 | X28: =+R28*(1-inputs_dec1!$C$42) -> 278.34889 | Y28: =+S28*(1-inputs_dec1!$C$43) -> 108.84374 | Z28: =+T28*(1-inputs_dec1!$C$44) -> 651.98075 | AA28: =+U28*(1-inputs_dec1!$C$45) -> 278.78784 | AC28: =+SUM(V28:AA28) -> 1867.4325
E29: 2500 | F29: =-(inputs_dec1!$C$4+SQRT(inputs_dec1!$C$4^2-4*inputs_dec1!$B$4*inputs_dec1!$D$4+4*inputs_dec1!$B$4*E29))/(2*inputs_dec1!$B$4) -> 36898.027 | G29: =-(inputs_dec1!$C$5+SQRT(inputs_dec1!$C$5^2-4*inputs_dec1!$B$5*inputs_dec1!$D$5+4*inputs_dec1!$B$5*E29))/(2*inputs_dec1!$B$5) -> 35916.061 | H29: =-(inputs_dec1!$C$6+SQRT(inputs_dec1!$C$6^2-4*inputs_dec1!$B$6*inputs_dec1!$D$6+4*inputs_dec1!$B$6*E29))/(2*inputs_dec1!$B$6) -> 39337.959 | I29: =+F29+G29+H29 -> 112152.05 | J29: =+inputs_dec1!$B$11*(E29-inputs_dec1!$B$54)+inputs_dec1!$C$11 -> 1184.0372 | K29: =+inputs_dec1!$B$12*(E29-inputs_dec1!$B$54)+inputs_dec1!$C$12 -> 1170.6323 | L29: =inputs_dec1!$B$13*(E29-inputs_dec1!$B$54)+inputs_dec1!$C$13 -> 469.42216 | M29: =+inputs_dec1!$B$14*(E29-inputs_dec1!$B$54)+inputs_dec1!$C$14 -> 479.96152 | N29: =+inputs_dec1!$B$15*(E29-inputs_dec1!$B$54)+inputs_dec1!$C$15 -> 516.57132 | O29: =+inputs_dec1!$B$16*(E29-inputs_dec1!$B$54)+inputs_dec1!$C$16 -> 321.14432 | P29: =inputs_dec1!$B$26*J29+inputs_dec1!$C$26 -> 1590.0772 | Q29: =inputs_dec1!$B$27*K29+inputs_dec1!$C$27 -> 781.61433 | R29: =inputs_dec1!$B$28*L29+inputs_dec1!$C$28 -> 580.95031 | S29: =inputs_dec1!$B$29*M29+inputs_dec1!$C$29 -> 171.72873 | T29: =inputs_dec1!$B$30*N29+inputs_dec1!$C$30 -> 722.99386 | U29: =inputs_dec1!$B$31*O29+inputs_dec1!$C$31 -> 330.11427 | V29: =+P29*(1-inputs_dec1!$C$40) -> 429.32085 | W29: =+Q29*(1-inputs_dec1!$C$41) -> 127.40314 | X29: =+R29*(1-inputs_dec1!$C$42) -> 267.23714 | Y29: =+S29*(1-inputs_dec1!$C$43) -> 108.1891 | Z29: =+T29*(1-inputs_dec1!$C$44) -> 650.69447 | AA29: =+U29*(1-inputs_dec1!$C$45) -> 280.59713 | AC29: =+SUM(V29:AA29) -> 1863.4418
E30: 2600 | F30: =-(inputs_dec1!$C$4+SQRT(inputs_dec1!$C$4^2-4*inputs_dec1!$B$4*inputs_dec1!$D$4+4*inputs_dec1!$B$4*E30))/(2*inputs_dec1!$B$4) -> 35316.244 | G30: =-(inputs_dec1!$C$5+SQRT(inputs_dec1!$C$5^2-4*inputs_dec1!$B$5*inputs_dec1!$D$5+4*inputs_dec1!$B$5*E30))/(2*inputs_dec1!$B$5) -> 34096.82 | H30: =-(inputs_dec1!$C$6+SQRT(inputs_dec1!$C$6^2-4*inputs_dec1!$B$6*inputs_dec1!$D$6+4*inputs_dec1!$B$6*E30))/(2*inputs_dec1!$B$6) -> 37585.172 | I30: =+F30+G30+H30 -> 106998.24 | J30: =+inputs_dec1!$B$11*(E30-inputs_dec1!$B$54)+inputs_dec1!$C$11 -> 1172.458 | K30: =+inputs_dec1!$B$12*(E30-inputs_dec1!$B$54)+inputs_dec1!$C$12 -> 1196.1816 | L30: =inputs_dec1!$B$13*(E30-inputs_dec1!$B$54)+inputs_dec1!$C$13 -> 455.52412 | M30: =+inputs_dec1!$B$14*(E30-inputs_dec1!$B$54)+inputs_dec1!$C$14 -> 471.04465 | N30: =+inputs_dec1!$B$15*(E30-inputs_dec1!$B$54)+inputs_dec1!$C$15 -> 515.76832 | O30: =+inputs_dec1!$B$16*(E30-inputs_dec1!$B$54)+inputs_dec1!$C$16 -> 324.28052 | P30: =inputs_dec1!$B$26*J30+inputs_dec1!$C$26 -> 1612.153 | Q30: =inputs_dec1!$B$27*K30+inputs_dec1!$C$27 -> 789.54244 | R30: =inputs_dec1!$B$28*L30+inputs_dec1!$C$28 -> 556.79433 | S30: =inputs_dec1!$B$29*M30+inputs_dec1!$C$29 -> 170.68962 | T30: =inputs_dec1!$B$30*N30+inputs_dec1!$C$30 -> 721.56466 | U30: =inputs_dec1!$B$31*O30+inputs_dec1!$C$31 -> 332.24284 | V30: =+P30*(1-inputs_dec1!$C$40) -> 435.28132 | W30: =+Q30*(1-inputs_dec1!$C$41) -> 128.69542 | X30: =+R30*(1-inputs_dec1!$C$42) -> 256.12539 | Y30: =+S30*(1-inputs_dec1!$C$43) -> 107.53446 | Z30: =+T30*(1-inputs_dec1!$C$44) -> 649.40819 | AA30: =+U30*(1-inputs_dec1!$C$45) -> 282.40641 | AC30: =+SUM(V30:AA30) -> 1859.4512
E31: 2700 | F31: =-(inputs_dec1!$C$4+SQRT(inputs_dec1!$C$4^2-4*inputs_dec1!$B$4*inputs_dec1!$D$4+4*inputs_dec1!$B$4*E31))/(2*inputs_dec1!$B$4) -> 33679.379 | G31: =-(inputs_dec1!$C$5+SQRT(inputs_dec1!$C$5^2-4*inputs_dec1!$B$5*inputs_dec1!$D$5+4*inputs_dec1!$B$5*E31))/(2*inputs_dec1!$B$5) -> 32143.393 | H31: =-(inputs_dec1!$C$6+SQRT(inputs_dec1!$C$6^2-4*inputs_dec1!$B$6*inputs_dec1!$D$6+4*inputs_dec1!$B$6*E31))/(2*inputs_dec1!$B$6) -> 35605.165 | I31: =+F31+G31+H31 -> 101427.94 | J31: =+inputs_dec1!$B$11*(E31-inputs_dec1!$B$54)+inputs_dec1!$C$11 -> 1160.8788 | K31: =+inputs_dec1!$B$12*(E31-inputs_dec1!$B$54)+inputs_dec1!$C$12 -> 1221.7309 | L31: =inputs_dec1!$B$13*(E31-inputs_dec1!$B$54)+inputs_dec1!$C$13 -> 441.62608 | M31: =+inputs_dec1!$B$14*(E31-inputs_dec1!$B$54)+inputs_dec1!$C$14 -> 462.12778 | N31: =+inputs_dec1!$B$15*(E31-inputs_dec1!$B$54)+inputs_dec1!$C$15 -> 514.96533 | O31: =+inputs_dec1!$B$16*(E31-inputs_dec1!$B$54)+inputs_dec1!$C$16 -> 327.41671 | P31: =inputs_dec1!$B$26*J31+inputs_dec1!$C$26 -> 1634.2288 | Q31: =inputs_dec1!$B$27*K31+inputs_dec1!$C$27 -> 797.47056 | R31: =inputs_dec1!$B$28*L31+inputs_dec1!$C$28 -> 532.63835 | S31: =inputs_dec1!$B$29*M31+inputs_dec1!$C$29 -> 169.65051 | T31: =inputs_dec1!$B$30*N31+inputs_dec1!$C$30 -> 720.13546 | U31: =inputs_dec1!$B$31*O31+inputs_dec1!$C$31 -> 334.3714 | V31: =+P31*(1-inputs_dec1!$C$40) -> 441.24179 | W31: =+Q31*(1-inputs_dec1!$C$41) -> 129.9877 | X31: =+R31*(1-inputs_dec1!$C$42) -> 245.01364 | Y31: =+S31*(1-inputs_dec1!$C$43) -> 106.87982 | Z31: =+T31*(1-inputs_dec1!$C$44) -> 648.12191 | AA31: =+U31*(1-inputs_dec1!$C$45) -> 284.21569 | AC31: =+SUM(V31:AA31) -> 1855.4606
E32: 2800 | F32: =-(inputs_dec1!$C$4+SQRT(inputs_dec1!$C$4^2-4*inputs_dec1!$B$4*inputs_dec1!$D$4+4*inputs_dec1!$B$4*E32))/(2*inputs_dec1!$B$4) -> 31981.244 | G32: =-(inputs_dec1!$C$5+SQRT(inputs_dec1!$C$5^2-4*inputs_dec1!$B$5*inputs_dec1!$D$5+4*inputs_dec1!$B$5*E32))/(2*inputs_dec1!$B$5) -> 30020.82 | H32: =-(inputs_dec1!$C$6+SQRT(inputs_dec1!$C$6^2-4*inputs_dec1!$B$6*inputs_dec1!$D$6+4*inputs_dec1!$B$6*E32))/(2*inputs_dec1!$B$6) -> 33276.776 | I32: =+F32+G32+H32 -> 95278.84 | J32: =+inputs_dec1!$B$11*(E32-inputs_dec1!$B$54)+inputs_dec1!$C$11 -> 1149.2997 | K32: =+inputs_dec1!$B$12*(E32-inputs_dec1!$B$54)+inputs_dec1!$C$12 -> 1247.2802 | L32: =inputs_dec1!$B$13*(E32-inputs_dec1!$B$54)+inputs_dec1!$C$13 -> 427.72803 | M32: =+inputs_dec1!$B$14*(E32-inputs_dec1!$B$54)+inputs_dec1!$C$14 -> 453.21092 | N32: =+inputs_dec1!$B$15*(E32-inputs_dec1!$B$54)+inputs_dec1!$C$15 -> 514.16234 | O32: =+inputs_dec1!$B$16*(E32-inputs_dec1!$B$54)+inputs_dec1!$C$16 -> 330.5529 | P32: =inputs_dec1!$B$26*J32+inputs_dec1!$C$26 -> 1656.3046 | Q32: =inputs_dec1!$B$27*K32+inputs_dec1!$C$27 -> 805.39867 | R32: =inputs_dec1!$B$28*L32+inputs_dec1!$C$28 -> 508.48237 | S32: =inputs_dec1!$B$29*M32+inputs_dec1!$C$29 -> 168.61139 | T32: =inputs_dec1!$B$30*N32+inputs_dec1!$C$30 -> 718.70626 | U32: =inputs_dec1!$B$31*O32+inputs_dec1!$C$31 -> 336.49997 | V32: =+P32*(1-inputs_dec1!$C$40) -> 447.20225 | W32: =+Q32*(1-inputs_dec1!$C$41) -> 131.27998 | X32: =+R32*(1-inputs_dec1!$C$42) -> 233.90189 | Y32: =+S32*(1-inputs_dec1!$C$43) -> 106.22518 | Z32: =+T32*(1-inputs_dec1!$C$44) -> 646.83563 | AA32: =+U32*(1-inputs_dec1!$C$45) -> 286.02498 | AC32: =+SUM(V32:AA32) -> 1851.4699
E33: 2900 | F33: =-(inputs_dec1!$C$4+SQRT(inputs_dec1!$C$4^2-4*inputs_dec1!$B$4*inputs_dec1!$D$4+4*inputs_dec1!$B$4*E33))/(2*inputs_dec1!$B$4) -> 30214.396 | G33: =-(inputs_dec1!$C$5+SQRT(inputs_dec1!$C$5^2-4*inputs_dec1!$B$5*inputs_dec1!$D$5+4*inputs_dec1!$B$5*E33))/(2*inputs_dec1!$B$5) -> 27675.666 | H33: =-(inputs_dec1!$C$6+SQRT(inputs_dec1!$C$6^2-4*inputs_dec1!$B$6*inputs_dec1!$D$6+4*inputs_dec1!$B$6*E33))/(2*inputs_dec1!$B$6) -> 30305.21 | I33: =+F33+G33+H33 -> 88195.272 | J33: =+inputs_dec1!$B$11*(E33-inputs_dec1!$B$54)+inputs_dec1!$C$11 -> 1137.7205 | K33: =+inputs_dec1!$B$12*(E33-inputs_dec1!$B$54)+inputs_dec1!$C$12 -> 1272.8295 | L33: =inputs_dec1!$B$13*(E33-inputs_dec1!$B$54)+inputs_dec1!$C$13 -> 413.82999 | M33: =+inputs_dec1!$B$14*(E33-inputs_dec1!$B$54)+inputs_dec1!$C$14 -> 444.29405 | N33: =+inputs_dec1!$B$15*(E33-inputs_dec1!$B$54)+inputs_dec1!$C$15 -> 513.35935 | O33: =+inputs_dec1!$B$16*(E33-inputs_dec1!$B$54)+inputs_dec1!$C$16 -> 333.68909 | P33: =inputs_dec1!$B$26*J33+inputs_dec1!$C$26 -> 1678.3804 | Q33: =inputs_dec1!$B$27*K33+inputs_dec1!$C$27 -> 813.32679 | R33: =inputs_dec1!$B$28*L33+inputs_dec1!$C$28 -> 484.32638 | S33: =inputs_dec1!$B$29*M33+inputs_dec1!$C$29 -> 167.57228 | T33: =inputs_dec1!$B$30*N33+inputs_dec1!$C$30 -> 717.27706 | U33: =inputs_dec1!$B$31*O33+inputs_dec1!$C$31 -> 338.62854 | V33: =+P33*(1-inputs_dec1!$C$40) -> 453.16272 | W33: =+Q33*(1-inputs_dec1!$C$41) -> 132.57227 | X33: =+R33*(1-inputs_dec1!$C$42) -> 222.79014 | Y33: =+S33*(1-inputs_dec1!$C$43) -> 105.57054 | Z33: =+T33*(1-inputs_dec1!$C$44) -> 645.54935 | AA33: =+U33*(1-inputs_dec1!$C$45) -> 287.83426 | AC33: =+SUM(V33:AA33) -> 1847.4793
E34: 3000 | F34: =-(inputs_dec1!$C$4+SQRT(inputs_dec1!$C$4^2-4*inputs_dec1!$B$4*inputs_dec1!$D$4+4*inputs_dec1!$B$4*E34))/(2*inputs_dec1!$B$4) -> 28369.75 | G34: =-(inputs_dec1!$C$5+SQRT(inputs_dec1!$C$5^2-4*inputs_dec1!$B$5*inputs_dec1!$D$5+4*inputs_dec1!$B$5*E34))/(2*inputs_dec1!$B$5) -> 25018.535 | H34: =-(inputs_dec1!$C$6+SQRT(inputs_dec1!$C$6^2-4*inputs_dec1!$B$6*inputs_dec1!$D$6+4*inputs_dec1!$B$6*E34))/(2*inputs_dec1!$B$6) -> 25150.242 | I34: =+F34+G34+H34 -> 78538.526 | J34: =+inputs_dec1!$B$11*(E34-inputs_dec1!$B$54)+inputs_dec1!$C$11 -> 1126.1413 | K34: =+inputs_dec1!$B$12*(E34-inputs_dec1!$B$54)+inputs_dec1!$C$12 -> 1298.3788 | L34: =inputs_dec1!$B$13*(E34-inputs_dec1!$B$54)+inputs_dec1!$C$13 -> 399.93195 | M34: =+inputs_dec1!$B$14*(E34-inputs_dec1!$B$54)+inputs_dec1!$C$14 -> 435.37718 | N34: =+inputs_dec1!$B$15*(E34-inputs_dec1!$B$54)+inputs_dec1!$C$15 -> 512.55636 | O34: =+inputs_dec1!$B$16*(E34-inputs_dec1!$B$54)+inputs_dec1!$C$16 -> 336.82529 | P34: =inputs_dec1!$B$26*J34+inputs_dec1!$C$26 -> 1700.4562 | Q34: =inputs_dec1!$B$27*K34+inputs_dec1!$C$27 -> 821.2549 | R34: =inputs_dec1!$B$28*L34+inputs_dec1!$C$28 -> 460.1704 | S34: =inputs_dec1!$B$29*M34+inputs_dec1!$C$29 -> 166.53316 | T34: =inputs_dec1!$B$30*N34+inputs_dec1!$C$30 -> 715.84786 | U34: =inputs_dec1!$B$31*O34+inputs_dec1!$C$31 -> 340.75711 | V34: =+P34*(1-inputs_dec1!$C$40) -> 459.12319 | W34: =+Q34*(1-inputs_dec1!$C$41) -> 133.86455 | X34: =+R34*(1-inputs_dec1!$C$42) -> 211.67839 | Y34: =+S34*(1-inputs_dec1!$C$43) -> 104.91589 | Z34: =+T34*(1-inputs_dec1!$C$44) -> 644.26307 | AA34: =+U34*(1-inputs_dec1!$C$45) -> 289.64354 | AC34: =+SUM(V34:AA34) -> 1843.4886
E37: 45641 | J37: BHP based on PF Pressure | P37: Liquid Rate | V37: Oil Rate
E38: Disch P | F38: A Machine | G38: B Machine | H38: C Machine | I38: Total CPF Output | J38: MPB-28 | K38: MPB-30 | L38: MPB-32 | M38: MPB-35 | N38: MPB-37 | O38: MPB-39 | P38: MPB-28 | Q38: MPB-30 | R38: MPB-32 | S38: MPB-35 | T38: MPB-37 | U38: MPB-39 | V38: MPB-28 | W38: MPB-30 | X38: MPB-32 | Y38: MPB-35 | Z38: MPB-37 | AA38: MPB-39 | AC38: Cum Oil
E39: 2200 | F39: =-(inputs_dec15!$C$4+SQRT(inputs_dec15!$C$4^2-4*inputs_dec15!$B$4*inputs_dec15!$D$4+4*inputs_dec15!$B$4*E39))/(2*inputs_dec15!$B$4) -> 41361.299 | G39: =-(inputs_dec15!$C$5+SQRT(inputs_dec15!$C$5^2-4*inputs_dec15!$B$5*inputs_dec15!$D$5+4*inputs_dec15!$B$5*E39))/(2*inputs_dec15!$B$5) -> 40781.578 | H39: =-(inputs_dec15!$C$6+SQRT(inputs_dec15!$C$6^2-4*inputs_dec15!$B$6*inputs_dec15!$D$6+4*inputs_dec15!$B$6*E39))/(2*inputs_dec15!$B$6) -> 43757.64 | I39: =+F39+G39+H39 -> 125900.52 | J39: =+inputs_dec15!$B$11*(E39-inputs_dec15!$B$55)+inputs_dec15!$C$11 -> 918.80008 | K39: =+inputs_dec15!$B$12*(E39-inputs_dec15!$B$55)+inputs_dec15!$C$12 -> 1093.9844 | L39: =inputs_dec15!$B$13*(E39-inputs_dec15!$B$55)+inputs_dec15!$C$13 -> 564.64077 | M39: =+inputs_dec15!$B$14*(E39-inputs_dec15!$B$55)+inputs_dec15!$C$14 -> 617.56498 | N39: =+inputs_dec15!$B$15*(E39-inputs_dec15!$B$55)+inputs_dec15!$C$15 -> 534.22995 | O39: =+inputs_dec15!$B$16*(E39-inputs_dec15!$B$55)+inputs_dec15!$C$16 -> 300.62449 | P39: =inputs_dec15!$B$26*J39+inputs_dec15!$C$26 -> 1901.0884 | Q39: =inputs_dec15!$B$27*K39+inputs_dec15!$C$27 -> 752.45083 | R39: =inputs_dec15!$B$28*L39+inputs_dec15!$C$28 -> 717.55712 | S39: =inputs_dec15!$B$29*M39+inputs_dec15!$C$29 -> 150.85324 | T39: =inputs_dec15!$B$30*N39+inputs_dec15!$C$30 -> 821.44277 | U39: =inputs_dec15!$B$31*O39+inputs_dec15!$C$31 -> 301.8571 | V39: =+P39*(1-inputs_dec15!$C$40) -> 513.29388 | W39: =+Q39*(1-inputs_dec15!$C$41) -> 122.64948 | X39: =+R39*(1-inputs_dec15!$C$42) -> 330.07627 | Y39: =+S39*(1-inputs_dec15!$C$43) -> 95.037539 | Z39: =+T39*(1-inputs_dec15!$C$44) -> 739.29849 | AA39: =+U39*(1-inputs_dec15!$C$45) -> 256.57853 | AC39: =+SUM(V39:AA39) -> 2056.9342
E40: 2300 | F40: =-(inputs_dec15!$C$4+SQRT(inputs_dec15!$C$4^2-4*inputs_dec15!$B$4*inputs_dec15!$D$4+4*inputs_dec15!$B$4*E40))/(2*inputs_dec15!$B$4) -> 39916.427 | G40: =-(inputs_dec15!$C$5+SQRT(inputs_dec15!$C$5^2-4*inputs_dec15!$B$5*inputs_dec15!$D$5+4*inputs_dec15!$B$5*E40))/(2*inputs_dec15!$B$5) -> 39242.833 | H40: =-(inputs_dec15!$C$6+SQRT(inputs_dec15!$C$6^2-4*inputs_dec15!$B$6*inputs_dec15!$D$6+4*inputs_dec15!$B$6*E40))/(2*inputs_dec15!$B$6) -> 42392.176 | I40: =+F40+G40+H40 -> 121551.44 | J40: =+inputs_dec15!$B$11*(E40-inputs_dec15!$B$55)+inputs_dec15!$C$11 -> 977.01832 | K40: =+inputs_dec15!$B$12*(E40-inputs_dec15!$B$55)+inputs_dec15!$C$12 -> 1119.5337 | L40: =inputs_dec15!$B$13*(E40-inputs_dec15!$B$55)+inputs_dec15!$C$13 -> 552.18862 | M40: =+inputs_dec15!$B$14*(E40-inputs_dec15!$B$55)+inputs_dec15!$C$14 -> 585.2845 | N40: =+inputs_dec15!$B$15*(E40-inputs_dec15!$B$55)+inputs_dec15!$C$15 -> 530.61531 | O40: =+inputs_dec15!$B$16*(E40-inputs_dec15!$B$55)+inputs_dec15!$C$16 -> 303.87283 | P40: =inputs_dec15!$B$26*J40+inputs_dec15!$C$26 -> 1759.1673 | Q40: =inputs_dec15!$B$27*K40+inputs_dec15!$C$27 -> 770.6255 | R40: =inputs_dec15!$B$28*L40+inputs_dec15!$C$28 -> 698.50434 | S40: =inputs_dec15!$B$29*M40+inputs_dec15!$C$29 -> 146.31808 | T40: =inputs_dec15!$B$30*N40+inputs_dec15!$C$30 -> 820.81894 | U40: =inputs_dec15!$B$31*O40+inputs_dec15!$C$31 -> 303.18473 | V40: =+P40*(1-inputs_dec15!$C$40) -> 474.97516 | W40: =+Q40*(1-inputs_dec15!$C$41) -> 125.61196 | X40: =+R40*(1-inputs_dec15!$C$42) -> 321.312 | Y40: =+S40*(1-inputs_dec15!$C$43) -> 92.180391 | Z40: =+T40*(1-inputs_dec15!$C$44) -> 738.73705 | AA40: =+U40*(1-inputs_dec15!$C$45) -> 257.70702 | AC40: =+SUM(V40:AA40) -> 2010.5236
E41: 2400 | F41: =-(inputs_dec15!$C$4+SQRT(inputs_dec15!$C$4^2-4*inputs_dec15!$B$4*inputs_dec15!$D$4+4*inputs_dec15!$B$4*E41))/(2*inputs_dec15!$B$4) -> 38429.942 | G41: =-(inputs_dec15!$C$5+SQRT(inputs_dec15!$C$5^2-4*inputs_dec15!$B$5*inputs_dec15!$D$5+4*inputs_dec15!$B$5*E41))/(2*inputs_dec15!$B$5) -> 37625.474 | H41: =-(inputs_dec15!$C$6+SQRT(inputs_dec15!$C$6^2-4*inputs_dec15!$B$6*inputs_dec15!$D$6+4*inputs_dec15!$B$6*E41))/(2*inputs_dec15!$B$6) -> 40927.427 | I41: =+F41+G41+H41 -> 116982.84 | J41: =+inputs_dec15!$B$11*(E41-inputs_dec15!$B$55)+inputs_dec15!$C$11 -> 1035.2366 | K41: =+inputs_dec15!$B$12*(E41-inputs_dec15!$B$55)+inputs_dec15!$C$12 -> 1145.083 | L41: =inputs_dec15!$B$13*(E41-inputs_dec15!$B$55)+inputs_dec15!$C$13 -> 539.73648 | M41: =+inputs_dec15!$B$14*(E41-inputs_dec15!$B$55)+inputs_dec15!$C$14 -> 553.00402 | N41: =+inputs_dec15!$B$15*(E41-inputs_dec15!$B$55)+inputs_dec15!$C$15 -> 527.00068 | O41: =+inputs_dec15!$B$16*(E41-inputs_dec15!$B$55)+inputs_dec15!$C$16 -> 307.12117 | P41: =inputs_dec15!$B$26*J41+inputs_dec15!$C$26 -> 1617.2461 | Q41: =inputs_dec15!$B$27*K41+inputs_dec15!$C$27 -> 788.80017 | R41: =inputs_dec15!$B$28*L41+inputs_dec15!$C$28 -> 679.45157 | S41: =inputs_dec15!$B$29*M41+inputs_dec15!$C$29 -> 141.78293 | T41: =inputs_dec15!$B$30*N41+inputs_dec15!$C$30 -> 820.19512 | U41: =inputs_dec15!$B$31*O41+inputs_dec15!$C$31 -> 304.51237 | V41: =+P41*(1-inputs_dec15!$C$40) -> 436.65644 | W41: =+Q41*(1-inputs_dec15!$C$41) -> 128.57443 | X41: =+R41*(1-inputs_dec15!$C$42) -> 312.54772 | Y41: =+S41*(1-inputs_dec15!$C$43) -> 89.323243 | Z41: =+T41*(1-inputs_dec15!$C$44) -> 738.1756 | AA41: =+U41*(1-inputs_dec15!$C$45) -> 258.83552 | AC41: =+SUM(V41:AA41) -> 1964.113
E42: 2500 | F42: =-(inputs_dec15!$C$4+SQRT(inputs_dec15!$C$4^2-4*inputs_dec15!$B$4*inputs_dec15!$D$4+4*inputs_dec15!$B$4*E42))/(2*inputs_dec15!$B$4) -> 36898.027 | G42: =-(inputs_dec15!$C$5+SQRT(inputs_dec15!$C$5^2-4*inputs_dec15!$B$5*inputs_dec15!$D$5+4*inputs_dec15!$B$5*E42))/(2*inputs_dec15!$B$5) -> 35916.061 | H42: =-(inputs_dec15!$C$6+SQRT(inputs_dec15!$C$6^2-4*inputs_dec15!$B$6*inputs_dec15!$D$6+4*inputs_dec15!$B$6*E42))/(2*inputs_dec15!$B$6) -> 39337.959 | I42: =+F42+G42+H42 -> 112152.05 | J42: =+inputs_dec15!$B$11*(E42-inputs_dec15!$B$55)+inputs_dec15!$C$11 -> 1093.4548 | K42: =+inputs_dec15!$B$12*(E42-inputs_dec15!$B$55)+inputs_dec15!$C$12 -> 1170.6323 | L42: =inputs_dec15!$B$13*(E42-inputs_dec15!$B$55)+inputs_dec15!$C$13 -> 527.28433 | M42: =+inputs_dec15!$B$14*(E42-inputs_dec15!$B$55)+inputs_dec15!$C$14 -> 520.72354 | N42: =+inputs_dec15!$B$15*(E42-inputs_dec15!$B$55)+inputs_dec15!$C$15 -> 523.38604 | O42: =+inputs_dec15!$B$16*(E42-inputs_dec15!$B$55)+inputs_dec15!$C$16 -> 310.36951 | P42: =inputs_dec15!$B$26*J42+inputs_dec15!$C$26 -> 1475.3249 | Q42: =inputs_dec15!$B$27*K42+inputs_dec15!$C$27 -> 806.97484 | R42: =inputs_dec15!$B$28*L42+inputs_dec15!$C$28 -> 660.3988 | S42: =inputs_dec15!$B$29*M42+inputs_dec15!$C$29 -> 137.24777 | T42: =inputs_dec15!$B$30*N42+inputs_dec15!$C$30 -> 819.57129 | U42: =inputs_dec15!$B$31*O42+inputs_dec15!$C$31 -> 305.84001 | V42: =+P42*(1-inputs_dec15!$C$40) -> 398.33772 | W42: =+Q42*(1-inputs_dec15!$C$41) -> 131.5369 | X42: =+R42*(1-inputs_dec15!$C$42) -> 303.78345 | Y42: =+S42*(1-inputs_dec15!$C$43) -> 86.466096 | Z42: =+T42*(1-inputs_dec15!$C$44) -> 737.61416 | AA42: =+U42*(1-inputs_dec15!$C$45) -> 259.96401 | AC42: =+SUM(V42:AA42) -> 1917.7023
E43: 2600 | F43: =-(inputs_dec15!$C$4+SQRT(inputs_dec15!$C$4^2-4*inputs_dec15!$B$4*inputs_dec15!$D$4+4*inputs_dec15!$B$4*E43))/(2*inputs_dec15!$B$4) -> 35316.244 | G43: =-(inputs_dec15!$C$5+SQRT(inputs_dec15!$C$5^2-4*inputs_dec15!$B$5*inputs_dec15!$D$5+4*inputs_dec15!$B$5*E43))/(2*inputs_dec15!$B$5) -> 34096.82 | H43: =-(inputs_dec15!$C$6+SQRT(inputs_dec15!$C$6^2-4*inputs_dec15!$B$6*inputs_dec15!$D$6+4*inputs_dec15!$B$6*E43))/(2*inputs_dec15!$B$6) -> 37585.172 | I43: =+F43+G43+H43 -> 106998.24 | J43: =+inputs_dec15!$B$11*(E43-inputs_dec15!$B$55)+inputs_dec15!$C$11 -> 1151.673 | K43: =+inputs_dec15!$B$12*(E43-inputs_dec15!$B$55)+inputs_dec15!$C$12 -> 1196.1816 | L43: =inputs_dec15!$B$13*(E43-inputs_dec15!$B$55)+inputs_dec15!$C$13 -> 514.83219 | M43: =+inputs_dec15!$B$14*(E43-inputs_dec15!$B$55)+inputs_dec15!$C$14 -> 488.44306 | N43: =+inputs_dec15!$B$15*(E43-inputs_dec15!$B$55)+inputs_dec15!$C$15 -> 519.77141 | O43: =+inputs_dec15!$B$16*(E43-inputs_dec15!$B$55)+inputs_dec15!$C$16 -> 313.61785 | P43: =inputs_dec15!$B$26*J43+inputs_dec15!$C$26 -> 1333.4037 | Q43: =inputs_dec15!$B$27*K43+inputs_dec15!$C$27 -> 825.14951 | R43: =inputs_dec15!$B$28*L43+inputs_dec15!$C$28 -> 641.34602 | S43: =inputs_dec15!$B$29*M43+inputs_dec15!$C$29 -> 132.71262 | T43: =inputs_dec15!$B$30*N43+inputs_dec15!$C$30 -> 818.94746 | U43: =inputs_dec15!$B$31*O43+inputs_dec15!$C$31 -> 307.16764 | V43: =+P43*(1-inputs_dec15!$C$40) -> 360.01901 | W43: =+Q43*(1-inputs_dec15!$C$41) -> 134.49937 | X43: =+R43*(1-inputs_dec15!$C$42) -> 295.01917 | Y43: =+S43*(1-inputs_dec15!$C$43) -> 83.608948 | Z43: =+T43*(1-inputs_dec15!$C$44) -> 737.05271 | AA43: =+U43*(1-inputs_dec15!$C$45) -> 261.0925 | AC43: =+SUM(V43:AA43) -> 1871.2917
E44: 2700 | F44: =-(inputs_dec15!$C$4+SQRT(inputs_dec15!$C$4^2-4*inputs_dec15!$B$4*inputs_dec15!$D$4+4*inputs_dec15!$B$4*E44))/(2*inputs_dec15!$B$4) -> 33679.379 | G44: =-(inputs_dec15!$C$5+SQRT(inputs_dec15!$C$5^2-4*inputs_dec15!$B$5*inputs_dec15!$D$5+4*inputs_dec15!$B$5*E44))/(2*inputs_dec15!$B$5) -> 32143.393 | H44: =-(inputs_dec15!$C$6+SQRT(inputs_dec15!$C$6^2-4*inputs_dec15!$B$6*inputs_dec15!$D$6+4*inputs_dec15!$B$6*E44))/(2*inputs_dec15!$B$6) -> 35605.165 | I44: =+F44+G44+H44 -> 101427.94 | J44: =+inputs_dec15!$B$11*(E44-inputs_dec15!$B$55)+inputs_dec15!$C$11 -> 1209.8913 | K44: =+inputs_dec15!$B$12*(E44-inputs_dec15!$B$55)+inputs_dec15!$C$12 -> 1221.7309 | L44: =inputs_dec15!$B$13*(E44-inputs_dec15!$B$55)+inputs_dec15!$C$13 -> 502.38004 | M44: =+inputs_dec15!$B$14*(E44-inputs_dec15!$B$55)+inputs_dec15!$C$14 -> 456.16257 | N44: =+inputs_dec15!$B$15*(E44-inputs_dec15!$B$55)+inputs_dec15!$C$15 -> 516.15677 | O44: =+inputs_dec15!$B$16*(E44-inputs_dec15!$B$55)+inputs_dec15!$C$16 -> 316.86619 | P44: =inputs_dec15!$B$26*J44+inputs_dec15!$C$26 -> 1191.4826 | Q44: =inputs_dec15!$B$27*K44+inputs_dec15!$C$27 -> 843.32418 | R44: =inputs_dec15!$B$28*L44+inputs_dec15!$C$28 -> 622.29325 | S44: =inputs_dec15!$B$29*M44+inputs_dec15!$C$29 -> 128.17746 | T44: =inputs_dec15!$B$30*N44+inputs_dec15!$C$30 -> 818.32363 | U44: =inputs_dec15!$B$31*O44+inputs_dec15!$C$31 -> 308.49528 | V44: =+P44*(1-inputs_dec15!$C$40) -> 321.70029 | W44: =+Q44*(1-inputs_dec15!$C$41) -> 137.46184 | X44: =+R44*(1-inputs_dec15!$C$42) -> 286.25489 | Y44: =+S44*(1-inputs_dec15!$C$43) -> 80.7518 | Z44: =+T44*(1-inputs_dec15!$C$44) -> 736.49127 | AA44: =+U44*(1-inputs_dec15!$C$45) -> 262.22099 | AC44: =+SUM(V44:AA44) -> 1824.8811
E45: 2800 | F45: =-(inputs_dec15!$C$4+SQRT(inputs_dec15!$C$4^2-4*inputs_dec15!$B$4*inputs_dec15!$D$4+4*inputs_dec15!$B$4*E45))/(2*inputs_dec15!$B$4) -> 31981.244 | G45: =-(inputs_dec15!$C$5+SQRT(inputs_dec15!$C$5^2-4*inputs_dec15!$B$5*inputs_dec15!$D$5+4*inputs_dec15!$B$5*E45))/(2*inputs_dec15!$B$5) -> 30020.82 | H45: =-(inputs_dec15!$C$6+SQRT(inputs_dec15!$C$6^2-4*inputs_dec15!$B$6*inputs_dec15!$D$6+4*inputs_dec15!$B$6*E45))/(2*inputs_dec15!$B$6) -> 33276.776 | I45: =+F45+G45+H45 -> 95278.84 | J45: =+inputs_dec15!$B$11*(E45-inputs_dec15!$B$55)+inputs_dec15!$C$11 -> 1268.1095 | K45: =+inputs_dec15!$B$12*(E45-inputs_dec15!$B$55)+inputs_dec15!$C$12 -> 1247.2802 | L45: =inputs_dec15!$B$13*(E45-inputs_dec15!$B$55)+inputs_dec15!$C$13 -> 489.9279 | M45: =+inputs_dec15!$B$14*(E45-inputs_dec15!$B$55)+inputs_dec15!$C$14 -> 423.88209 | N45: =+inputs_dec15!$B$15*(E45-inputs_dec15!$B$55)+inputs_dec15!$C$15 -> 512.54214 | O45: =+inputs_dec15!$B$16*(E45-inputs_dec15!$B$55)+inputs_dec15!$C$16 -> 320.11453 | P45: =inputs_dec15!$B$26*J45+inputs_dec15!$C$26 -> 1049.5614 | Q45: =inputs_dec15!$B$27*K45+inputs_dec15!$C$27 -> 861.49885 | R45: =inputs_dec15!$B$28*L45+inputs_dec15!$C$28 -> 603.24048 | S45: =inputs_dec15!$B$29*M45+inputs_dec15!$C$29 -> 123.64231 | T45: =inputs_dec15!$B$30*N45+inputs_dec15!$C$30 -> 817.6998 | U45: =inputs_dec15!$B$31*O45+inputs_dec15!$C$31 -> 309.82291 | V45: =+P45*(1-inputs_dec15!$C$40) -> 283.38157 | W45: =+Q45*(1-inputs_dec15!$C$41) -> 140.42431 | X45: =+R45*(1-inputs_dec15!$C$42) -> 277.49062 | Y45: =+S45*(1-inputs_dec15!$C$43) -> 77.894653 | Z45: =+T45*(1-inputs_dec15!$C$44) -> 735.92982 | AA45: =+U45*(1-inputs_dec15!$C$45) -> 263.34948 | AC45: =+SUM(V45:AA45) -> 1778.4705
E46: 2900 | F46: =-(inputs_dec15!$C$4+SQRT(inputs_dec15!$C$4^2-4*inputs_dec15!$B$4*inputs_dec15!$D$4+4*inputs_dec15!$B$4*E46))/(2*inputs_dec15!$B$4) -> 30214.396 | G46: =-(inputs_dec15!$C$5+SQRT(inputs_dec15!$C$5^2-4*inputs_dec15!$B$5*inputs_dec15!$D$5+4*inputs_dec15!$B$5*E46))/(2*inputs_dec15!$B$5) -> 27675.666 | H46: =-(inputs_dec15!$C$6+SQRT(inputs_dec15!$C$6^2-4*inputs_dec15!$B$6*inputs_dec15!$D$6+4*inputs_dec15!$B$6*E46))/(2*inputs_dec15!$B$6) -> 30305.21 | I46: =+F46+G46+H46 -> 88195.272 | J46: =+inputs_dec15!$B$11*(E46-inputs_dec15!$B$55)+inputs_dec15!$C$11 -> 1326.3277 | K46: =+inputs_dec15!$B$12*(E46-inputs_dec15!$B$55)+inputs_dec15!$C$12 -> 1272.8295 | L46: =inputs_dec15!$B$13*(E46-inputs_dec15!$B$55)+inputs_dec15!$C$13 -> 477.47575 | M46: =+inputs_dec15!$B$14*(E46-inputs_dec15!$B$55)+inputs_dec15!$C$14 -> 391.60161 | N46: =+inputs_dec15!$B$15*(E46-inputs_dec15!$B$55)+inputs_dec15!$C$15 -> 508.9275 | O46: =+inputs_dec15!$B$16*(E46-inputs_dec15!$B$55)+inputs_dec15!$C$16 -> 323.36287 | P46: =inputs_dec15!$B$26*J46+inputs_dec15!$C$26 -> 907.64021 | Q46: =inputs_dec15!$B$27*K46+inputs_dec15!$C$27 -> 879.67352 | R46: =inputs_dec15!$B$28*L46+inputs_dec15!$C$28 -> 584.1877 | S46: =inputs_dec15!$B$29*M46+inputs_dec15!$C$29 -> 119.10715 | T46: =inputs_dec15!$B$30*N46+inputs_dec15!$C$30 -> 817.07597 | U46: =inputs_dec15!$B$31*O46+inputs_dec15!$C$31 -> 311.15055 | V46: =+P46*(1-inputs_dec15!$C$40) -> 245.06286 | W46: =+Q46*(1-inputs_dec15!$C$41) -> 143.38678 | X46: =+R46*(1-inputs_dec15!$C$42) -> 268.72634 | Y46: =+S46*(1-inputs_dec15!$C$43) -> 75.037505 | Z46: =+T46*(1-inputs_dec15!$C$44) -> 735.36838 | AA46: =+U46*(1-inputs_dec15!$C$45) -> 264.47797 | AC46: =+SUM(V46:AA46) -> 1732.0598
E47: 3000 | F47: =-(inputs_dec15!$C$4+SQRT(inputs_dec15!$C$4^2-4*inputs_dec15!$B$4*inputs_dec15!$D$4+4*inputs_dec15!$B$4*E47))/(2*inputs_dec15!$B$4) -> 28369.75 | G47: =-(inputs_dec15!$C$5+SQRT(inputs_dec15!$C$5^2-4*inputs_dec15!$B$5*inputs_dec15!$D$5+4*inputs_dec15!$B$5*E47))/(2*inputs_dec15!$B$5) -> 25018.535 | H47: =-(inputs_dec15!$C$6+SQRT(inputs_dec15!$C$6^2-4*inputs_dec15!$B$6*inputs_dec15!$D$6+4*inputs_dec15!$B$6*E47))/(2*inputs_dec15!$B$6) -> 25150.242 | I47: =+F47+G47+H47 -> 78538.526 | J47: =+inputs_dec15!$B$11*(E47-inputs_dec15!$B$55)+inputs_dec15!$C$11 -> 1384.546 | K47: =+inputs_dec15!$B$12*(E47-inputs_dec15!$B$55)+inputs_dec15!$C$12 -> 1298.3788 | L47: =inputs_dec15!$B$13*(E47-inputs_dec15!$B$55)+inputs_dec15!$C$13 -> 465.02361 | M47: =+inputs_dec15!$B$14*(E47-inputs_dec15!$B$55)+inputs_dec15!$C$14 -> 359.32113 | N47: =+inputs_dec15!$B$15*(E47-inputs_dec15!$B$55)+inputs_dec15!$C$15 -> 505.31287 | O47: =+inputs_dec15!$B$16*(E47-inputs_dec15!$B$55)+inputs_dec15!$C$16 -> 326.61121 | P47: =inputs_dec15!$B$26*J47+inputs_dec15!$C$26 -> 765.71903 | Q47: =inputs_dec15!$B$27*K47+inputs_dec15!$C$27 -> 897.84819 | R47: =inputs_dec15!$B$28*L47+inputs_dec15!$C$28 -> 565.13493 | S47: =inputs_dec15!$B$29*M47+inputs_dec15!$C$29 -> 114.572 | T47: =inputs_dec15!$B$30*N47+inputs_dec15!$C$30 -> 816.45214 | U47: =inputs_dec15!$B$31*O47+inputs_dec15!$C$31 -> 312.47819 | V47: =+P47*(1-inputs_dec15!$C$40) -> 206.74414 | W47: =+Q47*(1-inputs_dec15!$C$41) -> 146.34926 | X47: =+R47*(1-inputs_dec15!$C$42) -> 259.96207 | Y47: =+S47*(1-inputs_dec15!$C$43) -> 72.180357 | Z47: =+T47*(1-inputs_dec15!$C$44) -> 734.80693 | AA47: =+U47*(1-inputs_dec15!$C$45) -> 265.60646 | AC47: =+SUM(V47:AA47) -> 1685.6492
E51: 45651 | F51: with 15Dec PF
E52: Disch P | F52: A Machine | G52: B Machine | H52: C Machine | I52: Total CPF Output | J52: MPB-28 | K52: MPB-30 | L52: MPB-32 | M52: MPB-35 | N52: MPB-37 | O52: MPB-39 | P52: MPB-28 | Q52: MPB-30 | R52: MPB-32 | S52: MPB-35 | T52: MPB-37 | U52: MPB-39 | V52: MPB-28 | W52: MPB-30 | X52: MPB-32 | Y52: MPB-35 | Z52: MPB-37 | AA52: MPB-39 | AC52: Cum Oil
E53: 2200 | F53: =-(inputs_dec25!$C$4+SQRT(inputs_dec25!$C$4^2-4*inputs_dec25!$B$4*inputs_dec25!$D$4+4*inputs_dec25!$B$4*E53))/(2*inputs_dec25!$B$4) -> 41361.299 | G53: =-(inputs_dec25!$C$5+SQRT(inputs_dec25!$C$5^2-4*inputs_dec25!$B$5*inputs_dec25!$D$5+4*inputs_dec25!$B$5*E53))/(2*inputs_dec25!$B$5) -> 40781.578 | H53: =-(inputs_dec25!$C$6+SQRT(inputs_dec25!$C$6^2-4*inputs_dec25!$B$6*inputs_dec25!$D$6+4*inputs_dec25!$B$6*E53))/(2*inputs_dec25!$B$6) -> 43757.64 | I53: =+F53+G53+H53 -> 125900.52 | J53: =+inputs_dec25!$B$11*(E53-inputs_dec25!$B$54)+inputs_dec25!$C$11 -> 918.80008 | K53: =+inputs_dec25!$B$12*(E53-inputs_dec25!$B$54)+inputs_dec25!$C$12 -> 1093.9844 | L53: =inputs_dec25!$B$13*(E53-inputs_dec25!$B$54)+inputs_dec25!$C$13 -> 564.64077 | M53: =+inputs_dec25!$B$14*(E53-inputs_dec25!$B$54)+inputs_dec25!$C$14 -> 617.56498 | N53: =+inputs_dec25!$B$15*(E53-inputs_dec25!$B$54)+inputs_dec25!$C$15 -> 534.22995 | O53: =+inputs_dec25!$B$16*(E53-inputs_dec25!$B$54)+inputs_dec25!$C$16 -> 300.62449 | P53: =inputs_dec25!$B$26*J53+inputs_dec25!$C$26 -> 2095.7542 | Q53: =inputs_dec25!$B$27*K53+inputs_dec25!$C$27 -> 749.28982 | R53: =inputs_dec25!$B$28*L53+inputs_dec25!$C$28 -> 816.45195 | S53: =inputs_dec25!$B$29*M53+inputs_dec25!$C$29 -> 181.17881 | T53: =inputs_dec25!$B$30*N53+inputs_dec25!$C$30 -> 832.9416 | U53: =inputs_dec25!$B$31*O53+inputs_dec25!$C$31 -> 331.15943 | V53: =+P53*(1-inputs_dec25!$C$39) -> 565.85364 | W53: =+Q53*(1-inputs_dec25!$C$40) -> 122.13424 | X53: =+R53*(1-inputs_dec25!$C$41) -> 375.5679 | Y53: =+S53*(1-inputs_dec25!$C$42) -> 114.14265 | Z53: =+T53*(1-inputs_dec25!$C$43) -> 749.64744 | AA53: =+U53*(1-inputs_dec25!$C$44) -> 281.48551 | AC53: =+SUM(V53:AA53) -> 2208.8314
E54: 2300 | F54: =-(inputs_dec25!$C$4+SQRT(inputs_dec25!$C$4^2-4*inputs_dec25!$B$4*inputs_dec25!$D$4+4*inputs_dec25!$B$4*E54))/(2*inputs_dec25!$B$4) -> 39916.427 | G54: =-(inputs_dec25!$C$5+SQRT(inputs_dec25!$C$5^2-4*inputs_dec25!$B$5*inputs_dec25!$D$5+4*inputs_dec25!$B$5*E54))/(2*inputs_dec25!$B$5) -> 39242.833 | H54: =-(inputs_dec25!$C$6+SQRT(inputs_dec25!$C$6^2-4*inputs_dec25!$B$6*inputs_dec25!$D$6+4*inputs_dec25!$B$6*E54))/(2*inputs_dec25!$B$6) -> 42392.176 | I54: =+F54+G54+H54 -> 121551.44 | J54: =+inputs_dec25!$B$11*(E54-inputs_dec25!$B$54)+inputs_dec25!$C$11 -> 977.01832 | K54: =+inputs_dec25!$B$12*(E54-inputs_dec25!$B$54)+inputs_dec25!$C$12 -> 1119.5337 | L54: =inputs_dec25!$B$13*(E54-inputs_dec25!$B$54)+inputs_dec25!$C$13 -> 552.18862 | M54: =+inputs_dec25!$B$14*(E54-inputs_dec25!$B$54)+inputs_dec25!$C$14 -> 585.2845 | N54: =+inputs_dec25!$B$15*(E54-inputs_dec25!$B$54)+inputs_dec25!$C$15 -> 530.61531 | O54: =+inputs_dec25!$B$16*(E54-inputs_dec25!$B$54)+inputs_dec25!$C$16 -> 303.87283 | P54: =inputs_dec25!$B$26*J54+inputs_dec25!$C$26 -> 1984.7606 | Q54: =inputs_dec25!$B$27*K54+inputs_dec25!$C$27 -> 817.7012 | R54: =inputs_dec25!$B$28*L54+inputs_dec25!$C$28 -> 812.61213 | S54: =inputs_dec25!$B$29*M54+inputs_dec25!$C$29 -> 175.07741 | T54: =inputs_dec25!$B$30*N54+inputs_dec25!$C$30 -> 836.80807 | U54: =inputs_dec25!$B$31*O54+inputs_dec25!$C$31 -> 351.85482 | V54: =+P54*(1-inputs_dec25!$C$39) -> 535.88536 | W54: =+Q54*(1-inputs_dec25!$C$40) -> 133.2853 | X54: =+R54*(1-inputs_dec25!$C$41) -> 373.80158 | Y54: =+S54*(1-inputs_dec25!$C$42) -> 110.29877 | Z54: =+T54*(1-inputs_dec25!$C$43) -> 753.12726 | AA54: =+U54*(1-inputs_dec25!$C$44) -> 299.0766 | AC54: =+SUM(V54:AA54) -> 2205.4749
E55: 2400 | F55: =-(inputs_dec25!$C$4+SQRT(inputs_dec25!$C$4^2-4*inputs_dec25!$B$4*inputs_dec25!$D$4+4*inputs_dec25!$B$4*E55))/(2*inputs_dec25!$B$4) -> 38429.942 | G55: =-(inputs_dec25!$C$5+SQRT(inputs_dec25!$C$5^2-4*inputs_dec25!$B$5*inputs_dec25!$D$5+4*inputs_dec25!$B$5*E55))/(2*inputs_dec25!$B$5) -> 37625.474 | H55: =-(inputs_dec25!$C$6+SQRT(inputs_dec25!$C$6^2-4*inputs_dec25!$B$6*inputs_dec25!$D$6+4*inputs_dec25!$B$6*E55))/(2*inputs_dec25!$B$6) -> 40927.427 | I55: =+F55+G55+H55 -> 116982.84 | J55: =+inputs_dec25!$B$11*(E55-inputs_dec25!$B$54)+inputs_dec25!$C$11 -> 1035.2366 | K55: =+inputs_dec25!$B$12*(E55-inputs_dec25!$B$54)+inputs_dec25!$C$12 -> 1145.083 | L55: =inputs_dec25!$B$13*(E55-inputs_dec25!$B$54)+inputs_dec25!$C$13 -> 539.73648 | M55: =+inputs_dec25!$B$14*(E55-inputs_dec25!$B$54)+inputs_dec25!$C$14 -> 553.00402 | N55: =+inputs_dec25!$B$15*(E55-inputs_dec25!$B$54)+inputs_dec25!$C$15 -> 527.00068 | O55: =+inputs_dec25!$B$16*(E55-inputs_dec25!$B$54)+inputs_dec25!$C$16 -> 307.12117 | P55: =inputs_dec25!$B$26*J55+inputs_dec25!$C$26 -> 1873.767 | Q55: =inputs_dec25!$B$27*K55+inputs_dec25!$C$27 -> 886.11258 | R55: =inputs_dec25!$B$28*L55+inputs_dec25!$C$28 -> 808.77232 | S55: =inputs_dec25!$B$29*M55+inputs_dec25!$C$29 -> 168.97601 | T55: =inputs_dec25!$B$30*N55+inputs_dec25!$C$30 -> 840.67454 | U55: =inputs_dec25!$B$31*O55+inputs_dec25!$C$31 -> 372.55022 | V55: =+P55*(1-inputs_dec25!$C$39) -> 505.91709 | W55: =+Q55*(1-inputs_dec25!$C$40) -> 144.43635 | X55: =+R55*(1-inputs_dec25!$C$41) -> 372.03527 | Y55: =+S55*(1-inputs_dec25!$C$42) -> 106.45488 | Z55: =+T55*(1-inputs_dec25!$C$43) -> 756.60708 | AA55: =+U55*(1-inputs_dec25!$C$44) -> 316.66768 | AC55: =+SUM(V55:AA55) -> 2202.1184
